2018-07-06 11:13:27,351 INFO: Microblog startup [in /home/cabbage/flask/flask-blog/app/errors.py:43]
2018-07-06 11:13:38,277 ERROR: Exception on /edit_profile [POST] [in /home/cabbage/flask/env/lib/python3.5/site-packages/flask/app.py:1761]
Traceback (most recent call last):
  File "/home/cabbage/flask/env/lib/python3.5/site-packages/sqlalchemy/engine/base.py", line 1193, in _execute_context
    context)
  File "/home/cabbage/flask/env/lib/python3.5/site-packages/sqlalchemy/engine/default.py", line 508, in do_execute
    cursor.execute(statement, parameters)
  File "/home/cabbage/flask/env/lib/python3.5/site-packages/pymysql/cursors.py", line 170, in execute
    result = self._query(query)
  File "/home/cabbage/flask/env/lib/python3.5/site-packages/pymysql/cursors.py", line 328, in _query
    conn.query(q)
  File "/home/cabbage/flask/env/lib/python3.5/site-packages/pymysql/connections.py", line 893, in query
    self._affected_rows = self._read_query_result(unbuffered=unbuffered)
  File "/home/cabbage/flask/env/lib/python3.5/site-packages/pymysql/connections.py", line 1103, in _read_query_result
    result.read()
  File "/home/cabbage/flask/env/lib/python3.5/site-packages/pymysql/connections.py", line 1396, in read
    first_packet = self.connection._read_packet()
  File "/home/cabbage/flask/env/lib/python3.5/site-packages/pymysql/connections.py", line 1059, in _read_packet
    packet.check_error()
  File "/home/cabbage/flask/env/lib/python3.5/site-packages/pymysql/connections.py", line 384, in check_error
    err.raise_mysql_exception(self._data)
  File "/home/cabbage/flask/env/lib/python3.5/site-packages/pymysql/err.py", line 109, in raise_mysql_exception
    raise errorclass(errno, errval)
pymysql.err.IntegrityError: (1062, "Duplicate entry 'cabbage' for key 'ix_user_username'")

The above exception was the direct cause of the following exception:

Traceback (most recent call last):
  File "/home/cabbage/flask/env/lib/python3.5/site-packages/flask/app.py", line 2292, in wsgi_app
    response = self.full_dispatch_request()
  File "/home/cabbage/flask/env/lib/python3.5/site-packages/flask/app.py", line 1815, in full_dispatch_request
    rv = self.handle_user_exception(e)
  File "/home/cabbage/flask/env/lib/python3.5/site-packages/flask/app.py", line 1718, in handle_user_exception
    reraise(exc_type, exc_value, tb)
  File "/home/cabbage/flask/env/lib/python3.5/site-packages/flask/_compat.py", line 35, in reraise
    raise value
  File "/home/cabbage/flask/env/lib/python3.5/site-packages/flask/app.py", line 1813, in full_dispatch_request
    rv = self.dispatch_request()
  File "/home/cabbage/flask/env/lib/python3.5/site-packages/flask/app.py", line 1799, in dispatch_request
    return self.view_functions[rule.endpoint](**req.view_args)
  File "/home/cabbage/flask/env/lib/python3.5/site-packages/flask_login/utils.py", line 261, in decorated_view
    return func(*args, **kwargs)
  File "/home/cabbage/flask/flask-blog/app/routes.py", line 86, in edit_profile
    db.session.commit()
  File "/home/cabbage/flask/env/lib/python3.5/site-packages/sqlalchemy/orm/scoping.py", line 153, in do
    return getattr(self.registry(), name)(*args, **kwargs)
  File "/home/cabbage/flask/env/lib/python3.5/site-packages/sqlalchemy/orm/session.py", line 943, in commit
    self.transaction.commit()
  File "/home/cabbage/flask/env/lib/python3.5/site-packages/sqlalchemy/orm/session.py", line 467, in commit
    self._prepare_impl()
  File "/home/cabbage/flask/env/lib/python3.5/site-packages/sqlalchemy/orm/session.py", line 447, in _prepare_impl
    self.session.flush()
  File "/home/cabbage/flask/env/lib/python3.5/site-packages/sqlalchemy/orm/session.py", line 2254, in flush
    self._flush(objects)
  File "/home/cabbage/flask/env/lib/python3.5/site-packages/sqlalchemy/orm/session.py", line 2380, in _flush
    transaction.rollback(_capture_exception=True)
  File "/home/cabbage/flask/env/lib/python3.5/site-packages/sqlalchemy/util/langhelpers.py", line 66, in __exit__
    compat.reraise(exc_type, exc_value, exc_tb)
  File "/home/cabbage/flask/env/lib/python3.5/site-packages/sqlalchemy/util/compat.py", line 187, in reraise
    raise value
  File "/home/cabbage/flask/env/lib/python3.5/site-packages/sqlalchemy/orm/session.py", line 2344, in _flush
    flush_context.execute()
  File "/home/cabbage/flask/env/lib/python3.5/site-packages/sqlalchemy/orm/unitofwork.py", line 391, in execute
    rec.execute(self)
  File "/home/cabbage/flask/env/lib/python3.5/site-packages/sqlalchemy/orm/unitofwork.py", line 556, in execute
    uow
  File "/home/cabbage/flask/env/lib/python3.5/site-packages/sqlalchemy/orm/persistence.py", line 177, in save_obj
    mapper, table, update)
  File "/home/cabbage/flask/env/lib/python3.5/site-packages/sqlalchemy/orm/persistence.py", line 768, in _emit_update_statements
    execute(statement, multiparams)
  File "/home/cabbage/flask/env/lib/python3.5/site-packages/sqlalchemy/engine/base.py", line 948, in execute
    return meth(self, multiparams, params)
  File "/home/cabbage/flask/env/lib/python3.5/site-packages/sqlalchemy/sql/elements.py", line 269, in _execute_on_connection
    return connection._execute_clauseelement(self, multiparams, params)
  File "/home/cabbage/flask/env/lib/python3.5/site-packages/sqlalchemy/engine/base.py", line 1060, in _execute_clauseelement
    compiled_sql, distilled_params
  File "/home/cabbage/flask/env/lib/python3.5/site-packages/sqlalchemy/engine/base.py", line 1200, in _execute_context
    context)
  File "/home/cabbage/flask/env/lib/python3.5/site-packages/sqlalchemy/engine/base.py", line 1413, in _handle_dbapi_exception
    exc_info
  File "/home/cabbage/flask/env/lib/python3.5/site-packages/sqlalchemy/util/compat.py", line 203, in raise_from_cause
    reraise(type(exception), exception, tb=exc_tb, cause=cause)
  File "/home/cabbage/flask/env/lib/python3.5/site-packages/sqlalchemy/util/compat.py", line 186, in reraise
    raise value.with_traceback(tb)
  File "/home/cabbage/flask/env/lib/python3.5/site-packages/sqlalchemy/engine/base.py", line 1193, in _execute_context
    context)
  File "/home/cabbage/flask/env/lib/python3.5/site-packages/sqlalchemy/engine/default.py", line 508, in do_execute
    cursor.execute(statement, parameters)
  File "/home/cabbage/flask/env/lib/python3.5/site-packages/pymysql/cursors.py", line 170, in execute
    result = self._query(query)
  File "/home/cabbage/flask/env/lib/python3.5/site-packages/pymysql/cursors.py", line 328, in _query
    conn.query(q)
  File "/home/cabbage/flask/env/lib/python3.5/site-packages/pymysql/connections.py", line 893, in query
    self._affected_rows = self._read_query_result(unbuffered=unbuffered)
  File "/home/cabbage/flask/env/lib/python3.5/site-packages/pymysql/connections.py", line 1103, in _read_query_result
    result.read()
  File "/home/cabbage/flask/env/lib/python3.5/site-packages/pymysql/connections.py", line 1396, in read
    first_packet = self.connection._read_packet()
  File "/home/cabbage/flask/env/lib/python3.5/site-packages/pymysql/connections.py", line 1059, in _read_packet
    packet.check_error()
  File "/home/cabbage/flask/env/lib/python3.5/site-packages/pymysql/connections.py", line 384, in check_error
    err.raise_mysql_exception(self._data)
  File "/home/cabbage/flask/env/lib/python3.5/site-packages/pymysql/err.py", line 109, in raise_mysql_exception
    raise errorclass(errno, errval)
sqlalchemy.exc.IntegrityError: (pymysql.err.IntegrityError) (1062, "Duplicate entry 'cabbage' for key 'ix_user_username'") [SQL: 'UPDATE user SET username=%(username)s, about_me=%(about_me)s WHERE user.id = %(user_id)s'] [parameters: {'user_id': 2, 'username': 'cabbage', 'about_me': ''}] (Background on this error at: http://sqlalche.me/e/gkpj)
2018-07-06 12:23:14,424 INFO: Microblog startup [in /home/cabbage/flask/flask-blog/app/errors.py:43]
2018-07-06 12:23:22,709 ERROR: Exception on /edit_profile [GET] [in /home/cabbage/flask/env/lib/python3.5/site-packages/flask/app.py:1761]
Traceback (most recent call last):
  File "/home/cabbage/flask/env/lib/python3.5/site-packages/flask/app.py", line 2292, in wsgi_app
    response = self.full_dispatch_request()
  File "/home/cabbage/flask/env/lib/python3.5/site-packages/flask/app.py", line 1815, in full_dispatch_request
    rv = self.handle_user_exception(e)
  File "/home/cabbage/flask/env/lib/python3.5/site-packages/flask/app.py", line 1718, in handle_user_exception
    reraise(exc_type, exc_value, tb)
  File "/home/cabbage/flask/env/lib/python3.5/site-packages/flask/_compat.py", line 35, in reraise
    raise value
  File "/home/cabbage/flask/env/lib/python3.5/site-packages/flask/app.py", line 1813, in full_dispatch_request
    rv = self.dispatch_request()
  File "/home/cabbage/flask/env/lib/python3.5/site-packages/flask/app.py", line 1799, in dispatch_request
    return self.view_functions[rule.endpoint](**req.view_args)
  File "/home/cabbage/flask/env/lib/python3.5/site-packages/flask_login/utils.py", line 261, in decorated_view
    return func(*args, **kwargs)
  File "/home/cabbage/flask/flask-blog/app/routes.py", line 82, in edit_profile
    form = EditProfileForm(current_user.username)
  File "/home/cabbage/flask/env/lib/python3.5/site-packages/wtforms/form.py", line 212, in __call__
    return type.__call__(cls, *args, **kwargs)
  File "/home/cabbage/flask/flask-blog/app/forms.py", line 36, in __init__
    super(EditProfileForm, self).__init__(*args, **kwargs)
NameError: name 'kwargs' is not defined
2018-07-06 12:25:09,747 INFO: Microblog startup [in /home/cabbage/flask/flask-blog/app/errors.py:43]
2018-07-06 13:46:32,749 INFO: Microblog startup [in /home/cabbage/flask/flask-blog/app/errors.py:43]
2018-07-06 14:39:17,902 INFO: Microblog startup [in /home/cabbage/flask/flask-blog/app/errors.py:43]
2018-07-06 14:39:30,173 INFO: Microblog startup [in /home/cabbage/flask/flask-blog/app/errors.py:43]
2018-07-06 16:32:07,347 INFO: Microblog startup [in /home/cabbage/flask/flask-blog/app/errors.py:43]
2018-07-06 16:40:21,690 INFO: Microblog startup [in /home/cabbage/flask/flask-blog/app/errors.py:43]
2018-07-06 16:41:39,237 INFO: Microblog startup [in /home/cabbage/flask/flask-blog/app/errors.py:43]
